tests/complex_14.in
40
o
9 S 100 ALIT 1754 317
17 S 101 AMPX 480 838
22 S 102 BHK 623 38
21 S 103 AWR 1249 140
39 B 104 AAP 1098 14
24 S 105 BDXB 1336 843
9 B 106 AIC 114 814
23 B 107 ARLO 957 787
2 S 108 AMCR 110 684
21 S 109 BAM 763 619
12 B 110 AXP 1763 565
10 B 111 BIP 738 745
4 S 112 APE 430 805
21 B 113 ARGO^A 471 998
6 S 114 BA 1991 175
11 B 115 AMAM 503 698
7 B 116 BGSF 1823 78
14 S 117 AMH 828 677
35 S 118 AJRD 185 631
18 B 119 ASX 1027 127
21 S 120 ATH^B 1979 688
14 B 121 AOMR 414 46
14 S 122 ABR^E 197 449
35 S 123 AWK 1106 476
20 S 124 AIRC 1170 844
11 B 125 AIRC 163 758
3 S 126 AVYA 1152 145
35 S 127 AQUA 1636 708
26 B 128 AQN 1634 997
19 B 129 AAIC 1202 973
7 B 130 ALLG 1626 812
35 S 131 AVAL 1761 52
16 S 132 BKT 301 558
29 S 133 AORT 1075 540
36 S 134 BBLN 118 266
28 B 135 ATI 1091 144
11 S 136 AMH^H 1411 303
21 S 137 BAC^P 545 974
5 S 138 AVK 1624 374
13 B 139 ATIP 222 173
3 B 140 BAC^S 702 200
16 S 141 ATUS 1854 845
38 S 142 ABR^E 1910 32
19 S 143 BC^C 1906 747
18 S 144 ABR 1273 891
15 S 145 AXS^E 1657 321
13 B 146 BCS 1945 505
36 B 147 AKA 1819 349
39 S 148 BIG 1344 145
7 B 149 AMOV 692 107
18 S 150 BAH 607 540
25 B 151 AUY 894 97
24 B 152 BIPH 1926 301
25 B 153 ACP^A 1322 251
27 B 154 BK 994 480
19 S 155 AWI 510 420
36 S 156 AQUA 1211 130
13 S 157 ATIP 111 799
34 B 158 ARGO 938 333
39 S 159 AJRD 1649 665
7 S 160 AHT^G 1429 546
17 S 161 ANAC 496 142
21 B 162 BMEZ 1789 517
31 B 163 AME 1311 686
31 S 164 AGM 527 494
4 S 165 ALTG 608 992
31 B 166 ASH 726 614
15 S 167 ABT 596 478
13 S 168 AU 1674 913
25 B 169 BMA 157 59
5 B 170 AIR 1124 381
24 S 171 ALLE 860 952
22 B 172 ALL^I 254 165
36 B 173 ACR^D 1449 692
22 S 174 AL 123 196
30 S 175 APTV^A 1074 38
39 S 176 BH 1285 130
33 S 177 ARC 1037 971
8 S 178 AQNA 397 166
15 B 179 AOS 1671 81
20 S 180 ANET 1400 740
23 S 181 BAC 1961 222
27 B 182 AEO 447 160
11 S 183 ATEN 113 377
23 B 184 ACR^C 656 929
28 S 185 BLX 1363 209
24 B 186 BIPC 607 268
7 S 187 AZO 864 888
30 B 188 BAC 534 123
14 B 189 ASA 1005 779
10 B 190 ADNT 1604 349
33 S 191 AGS 604 667
29 S 192 ARLO 1763 302
11 B 193 ACN 1536 731
6 B 194 BILL 1430 481
39 S 195 ARNC 1654 369
18 S 196 AWP 1291 903
4 B 197 BBDO 1974 440
20 B 198 BEPC 1490 713
38 B 199 AUD 1894 674
32 S 200 BML^G 1435 251
35 S 201 ACP^A 1748 151
27 B 202 BCO 234 785
6 B 203 ARE 861 541
32 S 204 BBD 588 840
4 B 205 ACA 1661 708
15 S 206 ACHR 728 752
3 S 207 BC^C 385 385
22 B 208 AIT 584 675
3 S 209 AAIC 1785 781
35 S 210 ASAI 736 600
36 S 211 ATH^C 524 156
38 S 212 BIT 1319 346
14 S 213 BF/A 1170 445
12 S 214 BBD 1553 779
18 B 215 BIP^A 1441 153
9 S 216 BG 1119 583
36 S 217 ANAC 203 326
14 B 218 ARMK 1619 203
10 B 219 AOD 1990 679
33 S 220 BAX 1463 964
24 S 221 BE 1360 450
21 B 222 BCS 1579 833
25 S 223 ARW 1314 620
9 B 224 AEL^B 1368 665
37 B 225 AZEK 1420 233
38 B 226 AAT 1895 566
22 S 227 BFLY 416 262
6 S 228 APD 1796 873
33 S 229 BFH 1007 451
12 B 230 AMH^G 141 347
17 S 231 BIPI 1325 32
16 B 232 BKSY 658 111
22 S 233 BIP^B 290 508
36 S 234 ALK 135 41
0 B 235 BGX 945 726
31 S 236 ATAQ 1131 397
7 B 237 AOD 1081 35
39 B 238 AGS 1810 808
12 S 239 BEP 1565 949
23 S 240 APG 409 278
0 S 241 APRN 1656 222
30 B 242 B 832 582
19 S 243 BLX 1147 199
7 S 244 ASA 1105 415
36 S 245 ASR 782 610
2 S 246 AWP 1140 554
7 S 247 AGM^E 1480 424
24 S 248 AEO 590 256
12 S 249 AFGC 580 339
23 S 250 ACN 294 58
27 B 251 BLND 687 578
6 S 252 AQNB 216 107
3 B 253 ANVS 1567 615
38 B 254 APO 480 775
12 S 255 AOMR 1527 51
25 S 256 ALL 1452 327
19 B 257 BDC 328 984
10 B 258 AAN 1846 307
30 B 259 AFB 1349 995
22 B 260 AMH^G 1394 481
11 S 261 AUD 198 711
37 B 262 BMI 1613 433
30 B 263 AMCR 1144 699
19 B 264 ATR 1888 754
8 B 265 AAIC^B 205 940
9 S 266 AFTR 184 568
34 B 267 AMH^H 298 364
33 S 268 ATH^C 519 112
4 S 269 AAIC 1881 121
23 S 270 ATUS 711 699
37 B 271 BIP^B 1979 985
20 S 272 APAM 1879 843
12 S 273 ABBV 1258 21
23 B 274 BAC^Q 1632 930
10 S 275 BFS^E 423 874
0 B 276 ATO 1659 676
2 B 277 AMAM 1559 546
21 B 278 BAC^O 510 512
25 S 279 ARR^C 819 124
37 B 280 BFZ 1864 599
15 B 281 ATAQ 532 543
38 S 282 BCS 1381 168
15 B 283 BC^B 1182 437
13 S 284 AIG 807 335
17 B 285 AMC 1304 443
30 B 286 AGS 1764 298
37 S 287 BIP^A 1123 977
28 S 288 ATCO^D 1175 166
39 S 289 AMWL 503 686
10 B 290 ACA 133 901
4 B 291 AZRE 531 586
10 S 292 BAC^M 1886 338
24 S 293 BHK 189 254
36 B 294 AJXA 672 88
2 B 295 BHR 1309 789
8 S 296 AFGC 1528 963
18 B 297 AGAC 794 645
21 S 298 ATI 1573 672
38 B 299 ARE 964 14
16 S 300 AHH^A 1697 643
10 S 301 ABR^E 1722 726
19 B 302 BAC^O 788 754
22 B 303 AES 887 366
1 S 304 BHG 1170 415
6 S 305 ARGO^A 728 696
17 B 306 BFK 1136 230
38 S 307 BML^G 894 823
32 S 308 ARGO^A 1343 656
21 B 309 ASB 1250 605
2 S 310 AL 1778 414
7 S 311 AFG 1544 455
11 B 312 AHT^G 398 812
22 S 313 ATHM 588 14
13 B 314 ATUS 1903 319
19 S 315 ABBV 1782 1000
7 S 316 BEN 1358 250
11 S 317 AB 802 295
17 S 318 ALL^B 417 191
9 S 319 ABR 1697 777
30 B 320 BALL 1193 534
2 S 321 AQUA 1032 945
12 S 322 ARMK 1525 315
37 S 323 AOS 1803 647
16 B 324 AGO 765 275
3 B 325 BGT 316 87
36 S 326 AMOV 732 534
37 S 327 BIP^A 1995 855
12 S 328 ABC 916 721
31 S 329 AEL^B 759 507
20 B 330 AVK 1558 494
37 S 331 BHP 1263 141
37 S 332 AQN 164 75
34 S 333 AP 446 197
11 B 334 BEP^A 1849 520
30 S 335 AEL 1862 967
19 B 336 BBUC 308 568
30 B 337 AMH 938 585
13 B 338 BMI 445 610
35 S 339 BML^H 1384 342
12 B 340 BAX 864 587
4 S 341 BIG 343 573
34 S 342 AOMR 1022 472
21 S 343 ATH^A 944 909
31 S 344 BABA 1255 367
3 S 345 AMH^G 1824 589
13 S 346 BAC^P 541 298
22 S 347 BK 158 151
16 B 348 AUD 1886 708
1 S 349 BERY 1033 300
32 B 350 AMP 1156 355
31 S 351 AIC 570 345
24 S 352 A 1907 53
11 S 353 AIRC 1997 761
16 S 354 BDJ 1751 236
37 B 355 BFK 435 864
7 S 356 AFGC 1753 595
22 S 357 ABBV 1922 678
9 B 358 ABR^E 948 828
2 S 359 BMAC 1505 329
8 S 360 BALY 1018 584
17 S 361 BILL 211 976
19 S 362 BEN 1868 428
25 B 363 BBWI 1381 491
6 S 364 AI 438 201
14 B 365 AMN 736 431
13 S 366 BANC 1153 261
19 B 367 BGH 1349 638
7 S 368 AMRX 197 504
12 S 369 ASAN 686 276
29 B 370 ATGE 1694 468
38 B 371 AIZ 1937 597
30 B 372 AL^A 1463 72
35 B 373 AMH^H 1495 801
3 B 374 ANAC 1964 976
31 B 375 ALLG 775 668
6 B 376 AGM^E 1013 863
6 S 377 BAX 233 507
29 B 378 BBN 1252 956
6 B 379 BKDT 509 196
10 B 380 ATEN 1309 435
10 B 381 ASAI 1410 565
35 S 382 BFZ 1479 74
7 S 383 ALE 1600 770
25 S 384 ALL^H 1893 999
25 S 385 BHG 237 357
15 B 386 AUB 807 688
37 S 387 APRN 888 873
38 S 388 AAIC^B 196 22
4 B 389 AQUA 1663 509
38 B 390 ACR^C 770 114
27 S 391 ATH^C 563 464
23 S 392 BKH 318 702
1 B 393 AU 1146 118
17 S 394 AGM 1784 596
12 S 395 ARES 1149 473
39 B 396 ALB 623 559
19 B 397 AGCO 1323 564
23 S 398 ALTG 869 192
38 B 399 ARR^C 1575 553
5 B 400 ASB^F 382 569
12 S 401 BIPH 1901 587
17 S 402 ACM 578 23
3 B 403 ARR^C 289 822
27 S 404 BKDT 1837 513
10 B 405 APG 1660 776
17 S 406 AESC 490 616
8 S 407 APD 1541 473
38 S 408 AFG 551 341
25 S 409 AVK 348 324
10 S 410 AMRC 1802 801
26 S 411 AHH^A 808 329
2 B 412 ARL 398 144
17 B 413 BHC 338 877
25 S 414 AIRC 1242 135
29 B 415 AEM 1284 740
6 B 416 AESC 1916 660
16 B 417 AME 399 135
30 S 418 AIN 1111 466
19 S 419 APGB 983 632
11 B 420 BLK 1031 536
15 S 421 APO 195 912
4 B 422 AVA 832 681
12 B 423 ARW 231 618
34 B 424 BKT 1686 369
28 B 425 AIRC 1676 697
29 S 426 ACM 1549 120
17 S 427 AIG^A 627 87
29 B 428 ARGD 1336 415
15 S 429 AAIN 696 447
37 B 430 BALY 1568 815
1 B 431 ALL^G 645 687
11 S 432 ARLO 1950 729
0 S 433 AMPX 996 918
17 B 434 ACM 1075 42
11 B 435 AHL^D 192 530
30 S 436 ABG 204 985
29 B 437 ABR^F 1513 452
22 S 438 AMG 1303 800
18 B 439 ADNT 1664 26
17 S 440 BDN 1057 466
10 S 441 BB 1353 296
8 B 442 ADX 1672 114
16 S 443 AMRC 648 761
4 B 444 AES 660 953
11 S 445 ALTG 1930 933
2 S 446 BBY 175 76
36 S 447 ADM 133 756
9 B 448 AGM^F 1090 482
23 S 449 AOS 336 247
6 B 450 AAP 489 420
22 S 451 AYI 1882 679
37 S 452 BIO/B 1910 939
35 S 453 AVD 1131 168
15 S 454 BGS 1377 968
24 B 455 AAIC^B 959 910
37 B 456 AMH^H 523 401
36 B 457 AIRC 1439 190
8 S 458 ACRE 843 940
20 B 459 BAC^Q 1705 145
13 S 460 AAIC^C 975 77
30 B 461 BC^A 865 383
24 B 462 APCA 1833 386
21 B 463 ACRE 656 867
18 B 464 BF/A 1511 293
