tests/complex_15.in
40
o
32 B 100 BFZ 1971 530
13 B 101 ATKR 134 303
0 S 102 AGS 736 310
31 B 103 BKDT 1876 740
0 B 104 AEL 1108 817
37 S 105 ASR 1140 292
10 S 106 ARNC 698 938
17 B 107 BEST 517 334
30 S 108 ABM 1659 194
3 B 109 ACRE 1624 28
8 S 110 AEFC 170 468
9 B 111 ARR^C 122 482
19 S 112 AQNB 1111 560
2 S 113 BIPI 228 841
13 B 114 BLCO 566 873
38 S 115 BIP 575 633
16 S 116 ABG 1068 57
34 S 117 BHC 786 547
26 B 118 ACR 1325 208
24 B 119 BEPH 1722 959
12 B 120 ATH^B 1150 110
10 S 121 AROC 842 41
25 S 122 BEDU 1816 170
33 S 123 ABB 970 594
6 B 124 AGM 529 450
34 B 125 BLUA 704 902
14 S 126 AMCR 130 617
16 S 127 AGTI 294 919
16 B 128 AAN 1867 468
21 S 129 AEL^A 1214 678
3 S 130 AHT^G 797 255
14 S 131 AIRC 312 383
5 B 132 AIRC 737 33
3 S 133 BAH 1450 71
33 S 134 BGX 102 102
36 S 135 AGM^D 212 314
17 S 136 BAP 1970 56
0 S 137 ASC 426 198
5 S 138 ACV 1131 176
15 S 139 BML^G 866 664
29 S 140 ALC 1992 154
8 S 141 AVD 326 464
27 S 142 ATCO^I 1141 973
8 S 143 BEP^A 851 167
31 S 144 ATAQ 520 307
30 S 145 BHLB 1921 52
11 B 146 BBVA 1801 206
26 S 147 ABT 276 693
16 B 148 ACM 1592 52
8 S 149 ABR^F 1629 443
37 B 150 AMWL 775 988
31 B 151 AMBC 1991 785
28 B 152 AGI 411 198
14 S 153 AIG^A 1991 643
10 S 154 ATR 1931 432
26 B 155 ATCO^I 1424 498
2 S 156 AGRO 1450 187
25 S 157 ATO 725 615
0 B 158 BIO/B 855 846
2 B 159 AXL 614 442
20 S 160 BHLB 1538 445
18 S 161 BB 440 665
35 B 162 BML^J 997 362
11 S 163 AAIC 857 400
13 B 164 ATH^B 458 507
20 B 165 BAC^M 1766 233
11 B 166 AHT^F 772 941
36 B 167 ATCO^I 450 681
10 B 168 ABT 823 803
5 B 169 AVNS 545 837
29 S 170 AES 1001 726
33 B 171 BIO/B 828 883
14 S 172 ARDC 463 909
15 B 173 ABB 334 72
30 S 174 AB 372 938
12 S 175 ADC 1681 532
5 B 176 AHL^D 176 846
28 B 177 AIR 1348 417
28 S 178 BG 1173 155
23 S 179 AYI 1503 449
36 B 180 AIG 1358 334
19 S 181 BAC^K 289 783
34 B 182 ATCO 667 111
15 B 183 BLND 877 664
30 S 184 ALG 763 747
20 S 185 ARMK 1663 595
19 S 186 BGH 889 518
39 S 187 ACR^C 156 809
19 B 188 BMAC 1449 361
4 S 189 ARCO 819 649
30 S 190 ATEK 1205 867
10 S 191 ABR^D 470 326
12 S 192 AVD 487 820
23 B 193 BCSF 1845 123
5 S 194 BIO 1187 297
36 B 195 APGB 620 930
6 B 196 BBWI 1540 50
27 S 197 BEP 1961 238
31 S 198 AFTR 1009 656
27 S 199 AEM 1153 117
16 S 200 ATTO 204 206
2 B 201 ARC 731 946
18 S 202 BC^B 1693 586
25 B 203 AGX 269 388
7 S 204 ARIS 1179 886
27 S 205 AWK 561 468
7 B 206 AP 726 565
38 S 207 AMCR 1806 943
39 S 208 APTV 109 927
24 B 209 ABR^E 948 476
32 S 210 BIT 1613 745
36 S 211 APTV^A 606 966
35 S 212 AROC 1693 80
3 B 213 ARCO 1286 617
10 S 214 AQNA 121 410
7 B 215 AEL^A 349 622
35 S 216 BHR 1276 74
11 S 217 BE 1898 549
5 B 218 ARIS 1206 222
11 S 219 BMI 1996 376
20 B 220 AIU 1649 57
29 B 221 AME 897 906
8 B 222 ACHR 1942 439
36 S 223 AAM^A 671 729
10 B 224 AIU 454 799
4 S 225 BFAM 1551 641
28 S 226 BAC 1516 511
25 S 227 BKT 510 577
31 S 228 AVY 659 64
15 B 229 AIG^A 922 47
17 S 230 AL^A 892 600
2 S 231 BEP 1333 491
35 B 232 AUB^A 1060 531
4 S 233 BLDR 1750 171
11 B 234 BAC^L 536 374
30 B 235 BAC^O 923 59
32 B 236 ACI 914 401
38 B 237 BFS^D 845 418
19 S 238 AMK 762 141
26 S 239 ASX 857 32
28 S 240 AORT 372 299
14 B 241 ARGO 947 77
26 S 242 APO 1645 218
26 B 243 BK 1895 251
37 B 244 BBDC 283 98
20 S 245 BEP^A 1630 351
10 B 246 BKT 1137 420
18 B 247 BHVN 1172 298
30 B 248 ASH 308 146
2 S 249 AZEK 411 56
36 S 250 ACM 415 286
1 S 251 ANF 111 549
18 S 252 BF/B 1796 867
1 B 253 ATR 674 117
6 S 254 BAP 1234 485
8 S 255 AEM 789 901
32 S 256 AGRO 249 466
18 S 257 AL^A 1588 494
8 S 258 BB 575 890
35 B 259 AQN 149 905
26 S 260 AL 339 569
31 B 261 ACP 1490 541
20 B 262 ASIX 1831 272
33 S 263 AA 1134 716
34 B 264 AIC 1541 915
29 B 265 ALL^H 1418 930
16 S 266 AFG 1212 121
26 S 267 AFG 268 731
2 B 268 ABR^D 163 33
28 S 269 AXS 324 572
18 B 270 BC 1551 701
6 S 271 BB 102 819
21 B 272 AIF 1038 37
38 S 273 BLCO 646 704
10 B 274 BIPI 1140 850
35 B 275 AYX 866 377
25 B 276 AU 1970 828
5 B 277 BAX 462 747
17 B 278 BAX 840 816
27 B 279 BAC^B 111 173
13 S 280 BIP 654 700
10 S 281 BLCO 203 968
11 B 282 BGY 348 610
1 B 283 AI 787 433
35 B 284 BCS 608 671
18 S 285 AMRC 766 759
39 S 286 AAIC^B 166 295
21 B 287 AZUL 742 354
10 S 288 BEPI 1276 158
4 B 289 ASB^E 1679 439
22 B 290 ADC^A 443 644
25 B 291 AFL 940 929
15 B 292 AGI 197 698
1 S 293 ARR^C 1845 832
19 S 294 ARI 1007 680
33 S 295 ARR^C 665 962
35 B 296 AFB 1306 403
33 S 297 AQNB 1158 715
29 B 298 AAN 596 734
8 S 299 ABR^F 134 413
17 B 300 ADX 1422 834
20 B 301 AQN 1044 225
28 S 302 AIO 141 820
3 B 303 ABM 826 408
15 B 304 ALEX 1479 907
12 B 305 AIZN 667 437
14 S 306 AJRD 1232 38
21 S 307 AES 1860 855
10 S 308 BEP 1013 332
20 S 309 BC^B 670 43
0 B 310 AMOV 1830 191
29 S 311 BLD 643 305
22 S 312 ALL^H 1740 871
27 B 313 AHT^F 1942 356
2 B 314 AMTD 487 636
32 B 315 BDX 1889 151
29 B 316 ACEL 668 796
8 B 317 ACRE 1750 518
32 B 318 ASX 905 44
5 S 319 BAC^S 514 246
20 B 320 BEP 1456 289
4 B 321 BHV 1023 654
19 B 322 BHR^D 263 254
38 S 323 ALLE 686 75
9 B 324 B 470 891
24 S 325 AMN 110 948
7 S 326 AQUA 1877 584
5 S 327 BACA 493 444
4 B 328 BFS^D 1819 225
19 S 329 BFZ 288 182
35 S 330 BIGZ 672 999
10 B 331 BHK 810 80
1 B 332 AUY 1325 82
9 B 333 AAM^A 1594 363
18 S 334 AGM^E 128 61
4 B 335 ARR^C 1954 135
28 B 336 AWK 695 825
32 S 337 AXR 1516 877
14 B 338 ATH^E 568 601
30 S 339 AL^A 422 345
39 B 340 AJRD 864 265
29 S 341 BAP 1350 636
30 S 342 AFB 1656 425
6 S 343 AEO 896 268
36 S 344 BAC^O 1949 35
17 B 345 ADNT 1029 559
26 S 346 BALL 1253 153
0 S 347 APGB 212 943
23 S 348 AESC 1875 966
13 S 349 ATAQ 307 109
32 B 350 BLW 1685 698
13 S 351 BGX 1213 738
4 B 352 BHIL 730 873
6 B 353 AGTI 1325 311
38 B 354 ATH^B 1937 321
7 B 355 AZRE 407 721
38 S 356 ALIT 1102 892
18 B 357 BAC^Q 449 768
26 S 358 BCSF 1239 110
36 S 359 AWI 1083 470
18 S 360 AWF 1474 813
38 S 361 BKU 190 172
13 S 362 AYI 1493 26
23 B 363 ATO 1199 839
26 S 364 AJRD 1135 62
13 B 365 ATH^E 1241 59
18 S 366 BH 346 283
16 B 367 AGS 1725 498
14 B 368 AQN 970 41
0 B 369 ARR^C 550 267
0 B 370 BC^B 880 508
10 B 371 AIG 647 766
33 B 372 BBDC 269 912
23 S 373 ABBV 265 384
14 S 374 BLK 869 599
27 B 375 ACDI 1069 895
6 B 376 ASGI 1090 271
19 S 377 BALL 813 827
17 S 378 AMPS 533 840
25 S 379 BB 352 304
22 S 380 BDN 1107 343
15 B 381 AEL^B 799 850
18 S 382 AEFC 1317 486
9 S 383 AJRD 1394 676
19 B 384 ATCO^I 1983 720
19 S 385 AVAL 1319 553
14 S 386 BGR 1032 128
31 S 387 AZO 795 482
5 S 388 AIG 1273 944
23 B 389 AMOV 1276 898
10 S 390 BMA 525 632
17 S 391 AOMR 1356 723
35 S 392 ATIP 595 534
33 S 393 AGTI 997 888
22 B 394 AZEK 1909 971
2 B 395 AQNB 1812 480
35 B 396 BIP^A 1444 275
14 S 397 AJG 320 609
20 S 398 AFGC 426 908
26 S 399 ALK 1010 491
31 S 400 ASAI 1506 796
14 B 401 APTV^A 827 789
6 S 402 ASAI 1308 514
37 S 403 ALTG 1341 81
10 S 404 AFT 1558 67
17 S 405 AFGE 1588 645
23 S 406 ATCO^D 1353 629
14 S 407 ALTG 1673 261
27 B 408 BIO 366 317
18 S 409 ARDC 1674 471
35 S 410 AOMR 594 666
21 S 411 BML^G 157 710
29 S 412 AAC 1993 253
0 S 413 AGD 201 198
12 B 414 AQNU 742 766
38 B 415 BHR 1536 116
25 B 416 ALL^H 485 883
5 S 417 AAM^B 1978 147
38 S 418 BLUA 972 471
8 S 419 AGCO 1309 729
31 B 420 AAN 724 349
35 B 421 ALLG 243 113
7 S 422 AFGC 438 620
38 S 423 BBDO 1570 787
24 B 424 APD 1085 629
7 B 425 AGTI 628 179
31 B 426 AIT 644 641
26 B 427 BB 1486 847
34 S 428 APTV 1923 207
22 B 429 AEL^B 809 103
13 S 430 ASPN 1052 105
34 B 431 AGRO 1119 255
39 B 432 BHR^B 354 144
16 B 433 BHP 993 256
33 S 434 ACRE 1972 565
38 B 435 AGM^F 841 417
6 B 436 AHT 1655 306
23 B 437 APG 957 195
29 B 438 ACI 929 688
10 B 439 AGM^E 1165 462
6 B 440 ASR 1636 151
35 S 441 ACV 475 243
23 S 442 ARES 1227 244
10 S 443 BAC^N 959 896
12 B 444 ATO 225 617
13 S 445 ADNT 863 490
10 B 446 ARGD 857 299
34 B 447 AVAL 950 236
24 B 448 AVNS 142 87
17 B 449 BIO 685 508
25 S 450 ABB 1493 977
33 B 451 BCO 286 23
37 S 452 AUB 1012 632
31 B 453 AJRD 1602 764
38 S 454 AFGC 408 668
23 S 455 BALL 1346 603
39 B 456 BH 1706 944
16 S 457 BCO 966 126
6 B 458 BAX 1463 717
24 S 459 ACA 1336 539
24 B 460 AKO/A 197 672
13 S 461 AZZ 645 677
16 S 462 ARES 826 998
9 B 463 ACM 1540 642
39 S 464 ATCO^H 422 573
12 S 465 AGM 1596 234
